{
    "dataType": "CVE_RECORD",
    "dataVersion": "5.1",
    "cveMetadata": {
        "cveId": "CVE-2025-8194",
        "assignerOrgId": "28c92f92-d60d-412d-b760-e73465c3df22",
        "state": "PUBLISHED",
        "assignerShortName": "PSF",
        "dateReserved": "2025-07-25T14:05:55.899Z",
        "datePublished": "2025-07-28T18:42:44.847Z",
        "dateUpdated": "2025-07-28T19:30:55.878Z"
    },
    "containers": {
        "cna": {
            "affected": [
                {
                    "defaultStatus": "unaffected",
                    "product": "CPython",
                    "repo": "https://github.com/python/cpython",
                    "vendor": "Python Software Foundation",
                    "versions": [
                        {
                            "version": "0",
                            "lessThan": "3.14.0",
                            "status": "affected",
                            "versionType": "python"
                        }
                    ]
                }
            ],
            "credits": [
                {
                    "lang": "en",
                    "type": "reporter",
                    "value": "Alexander Urieles"
                },
                {
                    "lang": "en",
                    "type": "coordinator",
                    "value": "Seth Larson"
                },
                {
                    "lang": "en",
                    "type": "remediation reviewer",
                    "value": "Ethan Furman"
                },
                {
                    "lang": "en",
                    "type": "remediation reviewer",
                    "value": "Steve Dower"
                }
            ],
            "descriptions": [
                {
                    "lang": "en",
                    "supportingMedia": [
                        {
                            "base64": false,
                            "type": "text/html",
                            "value": "There is a defect in the CPython “tarfile” module affecting the “TarFile” extraction and entry enumeration APIs. The tar implementation would process tar archives with negative offsets without error, resulting in an infinite loop and deadlock during the parsing of maliciously crafted tar archives. <br><br>This vulnerability can be mitigated by including the following patch after importing the “tarfile” module:<br><div><br></div><tt>import tarfile<br><br>def _block_patched(self, count):<br>&nbsp; &nbsp; if count &lt; 0:  # pragma: no cover<br>&nbsp; &nbsp; &nbsp; &nbsp; raise tarfile.InvalidHeaderError(\"invalid offset\")<br>&nbsp; &nbsp; return _block_patched._orig_block(self, count)<br><br>_block_patched._orig_block = tarfile.TarInfo._block<br>tarfile.TarInfo._block = _block_patched</tt><br>"
                        }
                    ],
                    "value": "There is a defect in the CPython “tarfile” module affecting the “TarFile” extraction and entry enumeration APIs. The tar implementation would process tar archives with negative offsets without error, resulting in an infinite loop and deadlock during the parsing of maliciously crafted tar archives. \n\nThis vulnerability can be mitigated by including the following patch after importing the “tarfile” module:\n\n\n\nimport tarfile\n\ndef _block_patched(self, count):\n    if count < 0:  # pragma: no cover\n        raise tarfile.InvalidHeaderError(\"invalid offset\")\n    return _block_patched._orig_block(self, count)\n\n_block_patched._orig_block = tarfile.TarInfo._block\ntarfile.TarInfo._block = _block_patched"
                }
            ],
            "metrics": [
                {
                    "cvssV3_1": {
                        "attackComplexity": "LOW",
                        "attackVector": "NETWORK",
                        "availabilityImpact": "HIGH",
                        "baseScore": 7.5,
                        "baseSeverity": "HIGH",
                        "confidentialityImpact": "NONE",
                        "integrityImpact": "NONE",
                        "privilegesRequired": "NONE",
                        "scope": "UNCHANGED",
                        "userInteraction": "NONE",
                        "vectorString": "CVSS:3.1/AV:N/AC:L/PR:N/UI:N/S:U/C:N/I:N/A:H",
                        "version": "3.1"
                    },
                    "format": "CVSS",
                    "scenarios": [
                        {
                            "lang": "en",
                            "value": "GENERAL"
                        }
                    ]
                }
            ],
            "problemTypes": [
                {
                    "descriptions": [
                        {
                            "cweId": "CWE-835",
                            "description": "CWE-835 Loop with Unreachable Exit Condition ('Infinite Loop')",
                            "lang": "en",
                            "type": "CWE"
                        }
                    ]
                }
            ],
            "providerMetadata": {
                "orgId": "28c92f92-d60d-412d-b760-e73465c3df22",
                "shortName": "PSF",
                "dateUpdated": "2025-07-28T19:30:55.878Z"
            },
            "references": [
                {
                    "tags": [
                        "issue-tracking"
                    ],
                    "url": "https://github.com/python/cpython/issues/130577"
                },
                {
                    "tags": [
                        "patch"
                    ],
                    "url": "https://github.com/python/cpython/pull/137027"
                },
                {
                    "tags": [
                        "vendor-advisory"
                    ],
                    "url": "https://mail.python.org/archives/list/security-announce@python.org/thread/ZULLF3IZ726XP5EY7XJ7YIN3K5MDYR2D/"
                },
                {
                    "tags": [
                        "patch"
                    ],
                    "url": "https://github.com/python/cpython/commit/7040aa54f14676938970e10c5f74ea93cd56aa38"
                },
                {
                    "tags": [
                        "patch"
                    ],
                    "url": "https://github.com/python/cpython/commit/cdae923ffe187d6ef916c0f665a31249619193fe"
                }
            ],
            "source": {
                "discovery": "UNKNOWN"
            },
            "title": "Tarfile infinite loop during parsing with negative member offset",
            "x_generator": {
                "engine": "Vulnogram 0.2.0"
            }
        },
        "adp": [
            {
                "metrics": [
                    {
                        "other": {
                            "type": "ssvc",
                            "content": {
                                "timestamp": "2025-07-28T18:57:54.114655Z",
                                "id": "CVE-2025-8194",
                                "options": [
                                    {
                                        "Exploitation": "none"
                                    },
                                    {
                                        "Automatable": "yes"
                                    },
                                    {
                                        "Technical Impact": "partial"
                                    }
                                ],
                                "role": "CISA Coordinator",
                                "version": "2.0.3"
                            }
                        }
                    }
                ],
                "title": "CISA ADP Vulnrichment",
                "providerMetadata": {
                    "orgId": "134c704f-9b21-4f2e-91b3-4a467353bcc0",
                    "shortName": "CISA-ADP",
                    "dateUpdated": "2025-07-28T18:57:59.093Z"
                }
            }
        ]
    }
}